**You:**

此代码报错：
代码如下：
# 读取两个数据框
email06_data = pd.read_csv("cleaned_email_06_full.csv")
email07_data = pd.read_csv("cleaned_email_07_full.csv")
email07_data['email_id'] = email07_data['email_id'].astype('str')

email_data = pd.concat([email06_data, email07_data], axis=0).reset_index(drop=True)
email_data['email_id'] = email_data['email_id'].astype('str')
email_data.to_csv("email_0607_full.csv",index=False)

email_data = pd.read_csv("email_0607_full.csv", dtype={'email_id': object})
print(email_data.info())
报错如下：
---------------------------------------------------------------------------
ParserError                               Traceback (most recent call last)
&lt;ipython-input-10-21c47b9285a2&gt; in &lt;cell line: 10&gt;()
      8 email_data.to_csv("email_0607_full.csv",index=False)
      9 
---&gt; 10 email_data = pd.read_csv("email_0607_full.csv", dtype={'email_id': object})
     11 print(email_data.info())

9 frames
/usr/local/lib/python3.9/dist-packages/pandas/util/_decorators.py in wrapper(*args, **kwargs)
    209                 else:
    210                     kwargs[new_arg_name] = new_arg_value
--&gt; 211             return func(*args, **kwargs)
    212 
    213         return cast(F, wrapper)

/usr/local/lib/python3.9/dist-packages/pandas/util/_decorators.py in wrapper(*args, **kwargs)
    329                     stacklevel=find_stack_level(),
    330                 )
--&gt; 331             return func(*args, **kwargs)
    332 
    333         # error: "Callable[[VarArg(Any), KwArg(Any)], Any]" has no

/usr/local/lib/python3.9/dist-packages/pandas/io/parsers/readers.py in read_csv(filepath_or_buffer, sep, delimiter, header, names, index_col, usecols, squeeze, prefix, mangle_dupe_cols, dtype, engine, converters, true_values, false_values, skipinitialspace, skiprows, skipfooter, nrows, na_values, keep_default_na, na_filter, verbose, skip_blank_lines, parse_dates, infer_datetime_format, keep_date_col, date_parser, dayfirst, cache_dates, iterator, chunksize, compression, thousands, decimal, lineterminator, quotechar, quoting, doublequote, escapechar, comment, encoding, encoding_errors, dialect, error_bad_lines, warn_bad_lines, on_bad_lines, delim_whitespace, low_memory, memory_map, float_precision, storage_options)
    948     kwds.update(kwds_defaults)
    949 
--&gt; 950     return _read(filepath_or_buffer, kwds)
    951 
    952 

/usr/local/lib/python3.9/dist-packages/pandas/io/parsers/readers.py in _read(filepath_or_buffer, kwds)
    609 
    610     with parser:
--&gt; 611         return parser.read(nrows)
    612 
    613 

/usr/local/lib/python3.9/dist-packages/pandas/io/parsers/readers.py in read(self, nrows)
   1776                     columns,
   1777                     col_dict,
-&gt; 1778                 ) = self._engine.read(  # type: ignore[attr-defined]
   1779                     nrows
   1780                 )

/usr/local/lib/python3.9/dist-packages/pandas/io/parsers/c_parser_wrapper.py in read(self, nrows)
    228         try:
    229             if self.low_memory:
--&gt; 230                 chunks = self._reader.read_low_memory(nrows)
    231                 # destructive to chunks
    232                 data = _concatenate_chunks(chunks)

/usr/local/lib/python3.9/dist-packages/pandas/_libs/parsers.pyx in pandas._libs.parsers.TextReader.read_low_memory()

/usr/local/lib/python3.9/dist-packages/pandas/_libs/parsers.pyx in pandas._libs.parsers.TextReader._read_rows()

/usr/local/lib/python3.9/dist-packages/pandas/_libs/parsers.pyx in pandas._libs.parsers.TextReader._tokenize_rows()

/usr/local/lib/python3.9/dist-packages/pandas/_libs/parsers.pyx in pandas._libs.parsers.raise_parser_error()

ParserError: Error tokenizing data. C error: Buffer overflow caught - possible malformed input file.

* * *

**ChatGPT:**

您的代码似乎在尝试读取"email\_0607\_full.csv"文件时遇到了问题。这可能是由于文件格式有误或文件损坏。根据报错提示，这可能是由于缓冲区溢出引起的，这通常意味着输入文件中存在一些不规范的数据。

为了解决这个问题，您可以尝试在`pd.read_csv()`中添加`error_bad_lines=False`参数，以忽略格式错误的行：

```python
email_data = pd.read_csv("email_0607_full.csv", dtype={'email_id': object}, error_bad_lines=False)
```

请注意，这将跳过格式错误的行，因此最终数据可能不完整。如果问题仍然存在，您可能需要检查"cleaned\_email\_06\_full.csv"和"cleaned\_email\_07\_full.csv"文件，确保它们的格式正确，并且没有损坏。

* * *

**You:**

仍然报错：
ParserError                               Traceback (most recent call last)
&lt;ipython-input-11-cb5e40a4f0c9&gt; in &lt;cell line: 1&gt;()
----&gt; 1 email_data = pd.read_csv("email_0607_full.csv", dtype={'email_id': object}, error_bad_lines=False)
      2 print(email_data.info())

9 frames
/usr/local/lib/python3.9/dist-packages/pandas/util/_decorators.py in wrapper(*args, **kwargs)
    209                 else:
    210                     kwargs[new_arg_name] = new_arg_value
--&gt; 211             return func(*args, **kwargs)
    212 
    213         return cast(F, wrapper)

/usr/local/lib/python3.9/dist-packages/pandas/util/_decorators.py in wrapper(*args, **kwargs)
    329                     stacklevel=find_stack_level(),
    330                 )
--&gt; 331             return func(*args, **kwargs)
    332 
    333         # error: "Callable[[VarArg(Any), KwArg(Any)], Any]" has no

/usr/local/lib/python3.9/dist-packages/pandas/io/parsers/readers.py in read_csv(filepath_or_buffer, sep, delimiter, header, names, index_col, usecols, squeeze, prefix, mangle_dupe_cols, dtype, engine, converters, true_values, false_values, skipinitialspace, skiprows, skipfooter, nrows, na_values, keep_default_na, na_filter, verbose, skip_blank_lines, parse_dates, infer_datetime_format, keep_date_col, date_parser, dayfirst, cache_dates, iterator, chunksize, compression, thousands, decimal, lineterminator, quotechar, quoting, doublequote, escapechar, comment, encoding, encoding_errors, dialect, error_bad_lines, warn_bad_lines, on_bad_lines, delim_whitespace, low_memory, memory_map, float_precision, storage_options)
    948     kwds.update(kwds_defaults)
    949 
--&gt; 950     return _read(filepath_or_buffer, kwds)
    951 
    952 

/usr/local/lib/python3.9/dist-packages/pandas/io/parsers/readers.py in _read(filepath_or_buffer, kwds)
    609 
    610     with parser:
--&gt; 611         return parser.read(nrows)
    612 
    613 

/usr/local/lib/python3.9/dist-packages/pandas/io/parsers/readers.py in read(self, nrows)
   1776                     columns,
   1777                     col_dict,
-&gt; 1778                 ) = self._engine.read(  # type: ignore[attr-defined]
   1779                     nrows
   1780                 )

/usr/local/lib/python3.9/dist-packages/pandas/io/parsers/c_parser_wrapper.py in read(self, nrows)
    228         try:
    229             if self.low_memory:
--&gt; 230                 chunks = self._reader.read_low_memory(nrows)
    231                 # destructive to chunks
    232                 data = _concatenate_chunks(chunks)

/usr/local/lib/python3.9/dist-packages/pandas/_libs/parsers.pyx in pandas._libs.parsers.TextReader.read_low_memory()

/usr/local/lib/python3.9/dist-packages/pandas/_libs/parsers.pyx in pandas._libs.parsers.TextReader._read_rows()

/usr/local/lib/python3.9/dist-packages/pandas/_libs/parsers.pyx in pandas._libs.parsers.TextReader._tokenize_rows()

/usr/local/lib/python3.9/dist-packages/pandas/_libs/parsers.pyx in pandas._libs.parsers.raise_parser_error()

ParserError: Error tokenizing data. C error: Buffer overflow caught - possible malformed input file.

* * *

**ChatGPT:**

我明白了，我们可以尝试另一种方法来解决这个问题。在这种情况下，您可以尝试使用Python的内置`open()`函数来打开文件，并查看是否有任何明显的格式问题。以下是一段示例代码，可以帮助您检查文件的前10行：

```python
with open("../data/email_0607_full.csv", "r", encoding="utf-8") as file:
    lines = [next(file) for _ in range(10)]
print("".join(lines))
```

如果文件内容看起来没有问题，您可以尝试使用`pd.read_csv()`的`chunksize`参数以分块方式读取文件。这种方法可以帮助您在处理大型文件时减少内存占用：

```python
chunksize = 5000  # 您可以根据需要调整此值
chunks = []

for chunk in pd.read_csv("email_0607_full.csv", dtype={'email_id': object}, chunksize=chunksize):
    chunks.append(chunk)

email_data = pd.concat(chunks, axis=0)
print(email_data.info())
```

如果以上方法仍然无法解决问题，那么问题可能源于"cleaned\_email\_06\_full.csv"和"cleaned\_email\_07\_full.csv"这两个源文件。您需要仔细检查这两个文件以确定其中是否存在格式问题或损坏的数据。

* * *

**You:**

两个源文件格式没问题，数据没损坏，使用Python的内置open()函数来打开文件没有问题

* * *

**ChatGPT:**

既然您已经确认了两个源文件和合并后的文件没有问题，我们可以尝试使用`pd.read_csv()`的另一个参数`engine='python'`来读取文件。这将使用Python引擎而不是默认的C引擎来读取文件，尽管速度可能会稍慢，但它可能能解决您遇到的问题。

请尝试以下代码：

```python
email_data = pd.read_csv("email_0607_full.csv", dtype={'email_id': object}, engine='python')
print(email_data.info())
```

如果仍然遇到问题，请确保您的pandas库是最新版本。如果不是，请升级到最新版本并重试：

```bash
pip install --upgrade pandas
```

如果以上所有方法都无法解决问题，您可能需要详细检查"email\_0607\_full.csv"文件以找到可能导致问题的特定行或数据。您可以尝试分段读取文件，并查看是否可以定位到特定的行或部分导致问题。例如，您可以尝试读取文件的前1000行，然后逐步增加行数，直到发现问题：

```python
nrows_to_test = 1000
while True:
    try:
        email_data = pd.read_csv("email_0607_full.csv", dtype={'email_id': object}, nrows=nrows_to_test, engine='python')
        print(f"Successfully read {nrows_to_test} rows.")
        nrows_to_test += 1000
    except Exception as e:
        print(f"Error encountered when trying to read {nrows_to_test} rows.")
        print(e)
        break
```

这段代码将逐步尝试读取更多行，直到遇到问题。这可以帮助您找到可能导致问题的特定行或部分。

* * *

**You:**

报错：
Error encountered when trying to read 1000 rows.
field larger than field limit (131072)

* * *

**ChatGPT:**

根据报错信息，看起来是某一行中的字段长度超过了Python的csv模块默认的最大字段限制（131072个字符）。您可以使用`csv.field_size_limit()`函数提高这个限制。请尝试以下代码：

首先，我们需要导入`csv`模块，并将字段大小限制提高到更大的值，例如2的25次方：

```python
import csv
csv.field_size_limit(2**25)  # 提高字段大小限制
```

然后，再次尝试使用Python引擎读取文件：

```python
email_data = pd.read_csv("email_0607_full.csv", dtype={'email_id': object}, engine='python')
print(email_data.info())
```

这应该可以解决由于字段长度超过限制导致的问题。